<?xml version="1.0" ?>

<!--Generates a urdf from the macro in sia5_macro.xacro -->
<robot name="motoman_sia5d" xmlns:xacro="http://ros.org/wiki/xacro">
    <xacro:arg name="prefix" default="yaskawa_"/>
	<xacro:include filename="$(find uclv_robot_ros)/urdf/robots/motoman_sia5f/sia5d_macro.xacro"/>
	<xacro:motoman_sia5d prefix="$(arg prefix)"/>

	<link name="$(arg prefix)pivoting_link" />
  
	<joint name="$(arg prefix)pivoting_joint" type="revolute" >
		<origin xyz="0.0 0 0.2" rpy="1.57079637 0 0"/>
		<parent link="$(arg prefix)tool0" />
		<child link="$(arg prefix)pivoting_link" />
		<limit effort="0" lower="-1.57079637" upper="1.57079637" velocity="6.10865255"/>
		<axis xyz="0 0 -1"/>
	</joint>
</robot>

